2022-09-17 22:58:33,559 ERROR: Exception on /edit_profile [GET] [in /home/zozo/PycharmProjects/microblog/venv/lib/python3.8/site-packages/flask/app.py:1741]
Traceback (most recent call last):
  File "/home/zozo/PycharmProjects/microblog/venv/lib/python3.8/site-packages/flask/app.py", line 2525, in wsgi_app
    response = self.full_dispatch_request()
  File "/home/zozo/PycharmProjects/microblog/venv/lib/python3.8/site-packages/flask/app.py", line 1822, in full_dispatch_request
    rv = self.handle_user_exception(e)
  File "/home/zozo/PycharmProjects/microblog/venv/lib/python3.8/site-packages/flask/app.py", line 1820, in full_dispatch_request
    rv = self.dispatch_request()
  File "/home/zozo/PycharmProjects/microblog/venv/lib/python3.8/site-packages/flask/app.py", line 1796, in dispatch_request
    return self.ensure_sync(self.view_functions[rule.endpoint])(**view_args)
  File "/home/zozo/PycharmProjects/microblog/venv/lib/python3.8/site-packages/flask_login/utils.py", line 290, in decorated_view
    return current_app.ensure_sync(func)(*args, **kwargs)
  File "/home/zozo/PycharmProjects/microblog/app/routes.py", line 78, in edit_profile
    if form.validate_on_submit():
NameError: name 'form' is not defined
2022-09-17 22:59:21,227 INFO: Microblog startup [in /home/zozo/PycharmProjects/microblog/app/__init__.py:45]
2022-09-17 22:59:25,440 ERROR: Exception on /edit_profile [GET] [in /home/zozo/PycharmProjects/microblog/venv/lib/python3.8/site-packages/flask/app.py:1741]
Traceback (most recent call last):
  File "/home/zozo/PycharmProjects/microblog/venv/lib/python3.8/site-packages/flask/app.py", line 2525, in wsgi_app
    response = self.full_dispatch_request()
  File "/home/zozo/PycharmProjects/microblog/venv/lib/python3.8/site-packages/flask/app.py", line 1822, in full_dispatch_request
    rv = self.handle_user_exception(e)
  File "/home/zozo/PycharmProjects/microblog/venv/lib/python3.8/site-packages/flask/app.py", line 1820, in full_dispatch_request
    rv = self.dispatch_request()
  File "/home/zozo/PycharmProjects/microblog/venv/lib/python3.8/site-packages/flask/app.py", line 1796, in dispatch_request
    return self.ensure_sync(self.view_functions[rule.endpoint])(**view_args)
  File "/home/zozo/PycharmProjects/microblog/venv/lib/python3.8/site-packages/flask_login/utils.py", line 290, in decorated_view
    return current_app.ensure_sync(func)(*args, **kwargs)
  File "/home/zozo/PycharmProjects/microblog/app/routes.py", line 78, in edit_profile
    if form.validate_on_submit():
NameError: name 'form' is not defined
2022-09-18 00:04:18,355 INFO: Microblog startup [in /home/zozo/PycharmProjects/microblog/app/__init__.py:45]
2022-09-18 00:11:17,983 INFO: Microblog startup [in /home/zozo/PycharmProjects/microblog/app/__init__.py:44]
2022-09-18 00:11:33,348 ERROR: Exception on / [GET] [in /home/zozo/PycharmProjects/microblog/venv/lib/python3.8/site-packages/flask/app.py:1741]
Traceback (most recent call last):
  File "/home/zozo/PycharmProjects/microblog/venv/lib/python3.8/site-packages/flask/app.py", line 2525, in wsgi_app
    response = self.full_dispatch_request()
  File "/home/zozo/PycharmProjects/microblog/venv/lib/python3.8/site-packages/flask/app.py", line 1822, in full_dispatch_request
    rv = self.handle_user_exception(e)
  File "/home/zozo/PycharmProjects/microblog/venv/lib/python3.8/site-packages/flask/app.py", line 1820, in full_dispatch_request
    rv = self.dispatch_request()
  File "/home/zozo/PycharmProjects/microblog/venv/lib/python3.8/site-packages/flask/app.py", line 1796, in dispatch_request
    return self.ensure_sync(self.view_functions[rule.endpoint])(**view_args)
  File "/home/zozo/PycharmProjects/microblog/venv/lib/python3.8/site-packages/flask_login/utils.py", line 290, in decorated_view
    return current_app.ensure_sync(func)(*args, **kwargs)
  File "/home/zozo/PycharmProjects/microblog/app/routes.py", line 23, in index
    page, app.config['POST_PER_PAGE', False])
KeyError: ('POST_PER_PAGE', False)
2022-09-18 00:11:38,625 ERROR: Exception on /index [GET] [in /home/zozo/PycharmProjects/microblog/venv/lib/python3.8/site-packages/flask/app.py:1741]
Traceback (most recent call last):
  File "/home/zozo/PycharmProjects/microblog/venv/lib/python3.8/site-packages/flask/app.py", line 2525, in wsgi_app
    response = self.full_dispatch_request()
  File "/home/zozo/PycharmProjects/microblog/venv/lib/python3.8/site-packages/flask/app.py", line 1822, in full_dispatch_request
    rv = self.handle_user_exception(e)
  File "/home/zozo/PycharmProjects/microblog/venv/lib/python3.8/site-packages/flask/app.py", line 1820, in full_dispatch_request
    rv = self.dispatch_request()
  File "/home/zozo/PycharmProjects/microblog/venv/lib/python3.8/site-packages/flask/app.py", line 1796, in dispatch_request
    return self.ensure_sync(self.view_functions[rule.endpoint])(**view_args)
  File "/home/zozo/PycharmProjects/microblog/venv/lib/python3.8/site-packages/flask_login/utils.py", line 290, in decorated_view
    return current_app.ensure_sync(func)(*args, **kwargs)
  File "/home/zozo/PycharmProjects/microblog/app/routes.py", line 23, in index
    page, app.config['POST_PER_PAGE', False])
KeyError: ('POST_PER_PAGE', False)
2022-09-18 00:12:25,267 INFO: Microblog startup [in /home/zozo/PycharmProjects/microblog/app/__init__.py:44]
2022-09-18 00:12:52,426 ERROR: Exception on /explore [GET] [in /home/zozo/PycharmProjects/microblog/venv/lib/python3.8/site-packages/flask/app.py:1741]
Traceback (most recent call last):
  File "/home/zozo/PycharmProjects/microblog/venv/lib/python3.8/site-packages/flask/app.py", line 2525, in wsgi_app
    response = self.full_dispatch_request()
  File "/home/zozo/PycharmProjects/microblog/venv/lib/python3.8/site-packages/flask/app.py", line 1822, in full_dispatch_request
    rv = self.handle_user_exception(e)
  File "/home/zozo/PycharmProjects/microblog/venv/lib/python3.8/site-packages/flask/app.py", line 1820, in full_dispatch_request
    rv = self.dispatch_request()
  File "/home/zozo/PycharmProjects/microblog/venv/lib/python3.8/site-packages/flask/app.py", line 1796, in dispatch_request
    return self.ensure_sync(self.view_functions[rule.endpoint])(**view_args)
  File "/home/zozo/PycharmProjects/microblog/venv/lib/python3.8/site-packages/flask_login/utils.py", line 290, in decorated_view
    return current_app.ensure_sync(func)(*args, **kwargs)
  File "/home/zozo/PycharmProjects/microblog/app/routes.py", line 129, in explore
    return render_template("index.html", title="Explore", posts=posts)
  File "/home/zozo/PycharmProjects/microblog/venv/lib/python3.8/site-packages/flask/templating.py", line 147, in render_template
    return _render(app, template, context)
  File "/home/zozo/PycharmProjects/microblog/venv/lib/python3.8/site-packages/flask/templating.py", line 130, in _render
    rv = template.render(context)
  File "/home/zozo/PycharmProjects/microblog/venv/lib/python3.8/site-packages/jinja2/environment.py", line 1301, in render
    self.environment.handle_exception()
  File "/home/zozo/PycharmProjects/microblog/venv/lib/python3.8/site-packages/jinja2/environment.py", line 936, in handle_exception
    raise rewrite_traceback_stack(source=source)
  File "/home/zozo/PycharmProjects/microblog/app/templates/index.html", line 1, in top-level template code
    {% extends "base.html" %}
  File "/home/zozo/PycharmProjects/microblog/app/templates/base.html", line 33, in top-level template code
    {% block content %}{% endblock %}
  File "/home/zozo/PycharmProjects/microblog/app/templates/index.html", line 18, in block 'content'
    {% for post in posts %}
TypeError: 'Pagination' object is not iterable
2022-09-18 00:15:16,882 ERROR: Exception on /explore [GET] [in /home/zozo/PycharmProjects/microblog/venv/lib/python3.8/site-packages/flask/app.py:1741]
Traceback (most recent call last):
  File "/home/zozo/PycharmProjects/microblog/venv/lib/python3.8/site-packages/flask/app.py", line 2525, in wsgi_app
    response = self.full_dispatch_request()
  File "/home/zozo/PycharmProjects/microblog/venv/lib/python3.8/site-packages/flask/app.py", line 1822, in full_dispatch_request
    rv = self.handle_user_exception(e)
  File "/home/zozo/PycharmProjects/microblog/venv/lib/python3.8/site-packages/flask/app.py", line 1820, in full_dispatch_request
    rv = self.dispatch_request()
  File "/home/zozo/PycharmProjects/microblog/venv/lib/python3.8/site-packages/flask/app.py", line 1796, in dispatch_request
    return self.ensure_sync(self.view_functions[rule.endpoint])(**view_args)
  File "/home/zozo/PycharmProjects/microblog/venv/lib/python3.8/site-packages/flask_login/utils.py", line 290, in decorated_view
    return current_app.ensure_sync(func)(*args, **kwargs)
  File "/home/zozo/PycharmProjects/microblog/app/routes.py", line 129, in explore
    return render_template("index.html", title="Explore", posts=posts)
  File "/home/zozo/PycharmProjects/microblog/venv/lib/python3.8/site-packages/flask/templating.py", line 147, in render_template
    return _render(app, template, context)
  File "/home/zozo/PycharmProjects/microblog/venv/lib/python3.8/site-packages/flask/templating.py", line 130, in _render
    rv = template.render(context)
  File "/home/zozo/PycharmProjects/microblog/venv/lib/python3.8/site-packages/jinja2/environment.py", line 1301, in render
    self.environment.handle_exception()
  File "/home/zozo/PycharmProjects/microblog/venv/lib/python3.8/site-packages/jinja2/environment.py", line 936, in handle_exception
    raise rewrite_traceback_stack(source=source)
  File "/home/zozo/PycharmProjects/microblog/app/templates/index.html", line 1, in top-level template code
    {% extends "base.html" %}
  File "/home/zozo/PycharmProjects/microblog/app/templates/base.html", line 33, in top-level template code
    {% block content %}{% endblock %}
  File "/home/zozo/PycharmProjects/microblog/app/templates/index.html", line 18, in block 'content'
    {% for post in posts %}
TypeError: 'Pagination' object is not iterable
2022-09-18 00:16:23,281 INFO: Microblog startup [in /home/zozo/PycharmProjects/microblog/app/__init__.py:44]
